[2024-06-04T18:00:12.213+0000] {task_context_logger.py:104} ERROR - Executor reports task instance <TaskInstance: reminder_about_accept_price.reminder_about_accept_price scheduled__2024-06-04T10:00:00+00:00 [queued]> finished (failed) although the task says it's queued. (Info: None) Was the task killed externally?
